<?xml version="1.0" ?>
<robot name="one_legged_robot">
  <!-- Base Link -->
  <link name="base_link">
    <visual>
      <geometry>
        <box size="0.1 0.1 0.1" />
      </geometry>
      <material name="gray"/>
    </visual>
  </link>

  <!-- Thigh Link -->
  <link name="thigh_link">
    <visual>
      <geometry>
        <cylinder length="0.15" radius="0.02"/>
      </geometry>
      <material name="blue"/>
    </visual>
  </link>

  <!-- Shank Link -->
  <link name="shank_link">
    <visual>
      <geometry>
        <cylinder length="0.10" radius="0.02"/>
      </geometry>
      <material name="red"/>
    </visual>
  </link>

  <!-- Hip Joint -->
  <joint name="hip_joint" type="revolute">
    <parent link="base_link"/>
    <child link="thigh_link"/>
    <origin xyz="0 0 0.05" rpy="0 0 0"/>
    <axis xyz="0 1 0"/>
    <limit lower="-0.785" upper="0.785" effort="10" velocity="1.0"/>
  </joint>

  <!-- Knee Joint -->
  <joint name="knee_joint" type="revolute">
    <parent link="thigh_link"/>
    <child link="shank_link"/>
    <origin xyz="0 0 -0.075" rpy="0 0 0"/>
    <axis xyz="0 1 0"/>
    <limit lower="-0.523" upper="0.523" effort="10" velocity="1.0"/>
  </joint>
</robot>
